<sdf version='1.7'>
  <world name='default'>
    <light name='sun' type='directional'>
      <cast_shadows>1</cast_shadows>
      <pose>0 0 10 0 -0 0</pose>
      <diffuse>0.8 0.8 0.8 1</diffuse>
      <specular>0.2 0.2 0.2 1</specular>
      <attenuation>
        <range>1000</range>
        <constant>0.9</constant>
        <linear>0.01</linear>
        <quadratic>0.001</quadratic>
      </attenuation>
      <direction>-0.5 0.1 -0.9</direction>
      <spot>
        <inner_angle>0</inner_angle>
        <outer_angle>0</outer_angle>
        <falloff>0</falloff>
      </spot>
    </light>
    <model name='ground_plane'>
      <static>1</static>
      <link name='link'>
        <collision name='collision'>
          <geometry>
            <plane>
              <normal>0 0 1</normal>
              <size>100 100</size>
            </plane>
          </geometry>
          <surface>
            <contact>
              <collide_bitmask>65535</collide_bitmask>
              <ode/>
            </contact>
            <friction>
              <ode>
                <mu>100</mu>
                <mu2>50</mu2>
              </ode>
              <torsional>
                <ode/>
              </torsional>
            </friction>
            <bounce/>
          </surface>
          <max_contacts>10</max_contacts>
        </collision>
        <visual name='visual'>
          <cast_shadows>0</cast_shadows>
          <geometry>
            <plane>
              <normal>0 0 1</normal>
              <size>100 100</size>
            </plane>
          </geometry>
          <material>
            <script>
              <uri>file://media/materials/scripts/gazebo.material</uri>
              <name>Gazebo/Grey</name>
            </script>
          </material>
        </visual>
        <self_collide>0</self_collide>
        <enable_wind>0</enable_wind>
        <kinematic>0</kinematic>
      </link>
    </model>
    <gravity>0 0 -9.8</gravity>
    <magnetic_field>6e-06 2.3e-05 -4.2e-05</magnetic_field>
    <atmosphere type='adiabatic'/>
    <physics type='ode'>
      <max_step_size>0.001</max_step_size>
      <real_time_factor>1</real_time_factor>
      <real_time_update_rate>1000</real_time_update_rate>
    </physics>
    <scene>
      <ambient>0.4 0.4 0.4 1</ambient>
      <background>0.7 0.7 0.7 1</background>
      <shadows>1</shadows>
    </scene>
    <wind/>
    <spherical_coordinates>
      <surface_model>EARTH_WGS84</surface_model>
      <latitude_deg>0</latitude_deg>
      <longitude_deg>0</longitude_deg>
      <elevation>0</elevation>
      <heading_deg>0</heading_deg>
    </spherical_coordinates>
    <model name='arm'>
      <link name='base_link'>
        <inertial>
          <pose>-0.00055 -0.005497 0.024988 0 -0 0</pose>
          <mass>0.2001</mass>
          <inertia>
            <ixx>1.20205e+08</ixx>
            <ixy>-6.05302e-07</ixy>
            <ixz>2.75137e-06</ixz>
            <iyy>1.07355e+08</iyy>
            <iyz>2.75137e-05</iyz>
            <izz>1.4843e+08</izz>
          </inertia>
        </inertial>
        <collision name='base_link_collision'>
          <pose>0 0 0 0 -0 0</pose>
          <geometry>
            <box>
              <size>0.1 0.1 0.1</size>
            </box>
          </geometry>
          <surface>
            <contact>
              <ode/>
            </contact>
            <friction>
              <ode/>
              <torsional>
                <ode/>
              </torsional>
            </friction>
            <bounce/>
          </surface>
          <max_contacts>10</max_contacts>
        </collision>
        <collision name='base_link_fixed_joint_lump__base_turn_collision_1'>
          <pose>-0.0011 0.001 0.051 0 -0 0</pose>
          <geometry>
            <box>
              <size>0.05 0.08 0.1</size>
            </box>
          </geometry>
          <surface>
            <contact>
              <ode/>
            </contact>
            <friction>
              <ode/>
              <torsional>
                <ode/>
              </torsional>
            </friction>
            <bounce/>
          </surface>
          <max_contacts>10</max_contacts>
        </collision>
        <collision name='base_link_fixed_joint_lump__camera_link_collision_2'>
          <pose>0 0 0 0 -0 0</pose>
          <geometry>
            <box>
              <size>0.02 0.08 0.05</size>
            </box>
          </geometry>
          <surface>
            <contact>
              <ode/>
            </contact>
            <friction>
              <ode/>
              <torsional>
                <ode/>
              </torsional>
            </friction>
            <bounce/>
          </surface>
          <max_contacts>10</max_contacts>
        </collision>
        <visual name='base_link_visual'>
          <pose>0 0 0 0 -0 0</pose>
          <geometry>
            <mesh>
              <scale>0.001 0.001 0.001</scale>
              <uri>/home/luigi/catkin_ws/src/arm_description/meshes/base_link.stl</uri>
            </mesh>
          </geometry>
          <material>
            <script>
              <name>Gazebo/Red</name>
              <uri>file://media/materials/scripts/gazebo.material</uri>
            </script>
          </material>
        </visual>
        <visual name='base_link_fixed_joint_lump__base_turn_visual_1'>
          <pose>-0.0011 -0.011 0.05 0 -0 0</pose>
          <geometry>
            <mesh>
              <scale>0.001 0.001 0.001</scale>
              <uri>/home/luigi/catkin_ws/src/arm_description/meshes/base_turn.stl</uri>
            </mesh>
          </geometry>
          <material>
            <script>
              <name>Gazebo/Red</name>
              <uri>file://media/materials/scripts/gazebo.material</uri>
            </script>
          </material>
        </visual>
        <visual name='base_link_fixed_joint_lump__camera_link_visual_2'>
          <pose>0 0 0 0 -0 0</pose>
          <geometry>
            <box>
              <size>0.02 0.08 0.05</size>
            </box>
          </geometry>
          <material>
            <script>
              <name>Gazebo/Green</name>
              <uri>file://media/materials/scripts/gazebo.material</uri>
            </script>
          </material>
        </visual>
        <sensor name='camera' type='camera'>
          <update_rate>30</update_rate>
          <camera name='head'>
            <horizontal_fov>1.39626</horizontal_fov>
            <image>
              <width>800</width>
              <height>600</height>
              <format>R8G8B8</format>
            </image>
            <clip>
              <near>0.02</near>
              <far>300</far>
            </clip>
            <noise>
              <type>gaussian</type>
              <mean>0</mean>
              <stddev>0.007</stddev>
            </noise>
          </camera>
          <plugin name='camera_controller' filename='libgazebo_ros_camera.so'>
            <alwaysOn>1</alwaysOn>
            <updateRate>0.0</updateRate>
            <cameraName>arm/camera</cameraName>
            <imageTopicName>image_raw</imageTopicName>
            <cameraInfoTopicName>camera_info</cameraInfoTopicName>
            <frameName>camera_link</frameName>
            <hackBaseline>0.07</hackBaseline>
            <distortionK1>0.0</distortionK1>
            <distortionK2>0.0</distortionK2>
            <distortionK3>0.0</distortionK3>
            <distortionT1>0.0</distortionT1>
            <distortionT2>0.0</distortionT2>
            <robotNamespace>/</robotNamespace>
          </plugin>
          <pose>0 0 0 0 -0 0</pose>
        </sensor>
        <self_collide>0</self_collide>
        <enable_wind>0</enable_wind>
        <kinematic>0</kinematic>
      </link>
      <joint name='j0' type='revolute'>
        <pose relative_to='base_link'>-0.0011 0.0045 0.063 0 0 -1.57</pose>
        <parent>base_link</parent>
        <child>base_turn_rot</child>
        <axis>
          <xyz>0 0 1</xyz>
          <limit>
            <lower>-2.57</lower>
            <upper>2.57</upper>
            <effort>300</effort>
            <velocity>0.1</velocity>
          </limit>
          <dynamics>
            <spring_reference>0</spring_reference>
            <spring_stiffness>0</spring_stiffness>
          </dynamics>
        </axis>
      </joint>
      <link name='base_turn_rot'>
        <pose relative_to='j0'>0 0 0 0 -0 0</pose>
        <inertial>
          <pose>0 0 0.01925 0 -0 0</pose>
          <mass>0.2</mass>
          <inertia>
            <ixx>3.42004e+06</ixx>
            <ixy>-0.0161328</ixy>
            <ixz>1.72099e-18</ixz>
            <iyy>2.85598e+06</iyy>
            <iyz>2.16116e-15</iyz>
            <izz>5.84321e+06</izz>
          </inertia>
        </inertial>
        <collision name='base_turn_rot_collision'>
          <pose>0 0 0 0 -0 0</pose>
          <geometry>
            <box>
              <size>0.06 0.06 0.027</size>
            </box>
          </geometry>
          <surface>
            <contact>
              <ode/>
            </contact>
            <friction>
              <ode/>
              <torsional>
                <ode/>
              </torsional>
            </friction>
            <bounce/>
          </surface>
          <max_contacts>10</max_contacts>
        </collision>
        <collision name='base_turn_rot_fixed_joint_lump__dyn2_collision_1'>
          <pose>0 0 0.0385 1.57159 1.57079 3.14159</pose>
          <geometry>
            <box>
              <size>0.08 0.035 0.045</size>
            </box>
          </geometry>
          <surface>
            <contact>
              <ode/>
            </contact>
            <friction>
              <ode/>
              <torsional>
                <ode/>
              </torsional>
            </friction>
            <bounce/>
          </surface>
          <max_contacts>10</max_contacts>
        </collision>
        <visual name='base_turn_rot_visual'>
          <pose>0 0 0 0 -0 0</pose>
          <geometry>
            <mesh>
              <scale>0.001 0.001 0.001</scale>
              <uri>/home/luigi/catkin_ws/src/arm_description/meshes/base_turn_table_rot.stl</uri>
            </mesh>
          </geometry>
          <material>
            <script>
              <name>Gazebo/Red</name>
              <uri>file://media/materials/scripts/gazebo.material</uri>
            </script>
          </material>
        </visual>
        <visual name='base_turn_rot_fixed_joint_lump__dyn2_visual_1'>
          <pose>0 0 0.0385 1.57159 1.57079 3.14159</pose>
          <geometry>
            <mesh>
              <scale>0.01 0.01 0.01</scale>
              <uri>/home/luigi/catkin_ws/src/arm_description/meshes/dyn.stl</uri>
            </mesh>
          </geometry>
          <material>
            <script>
              <name>Gazebo/Black</name>
              <uri>file://media/materials/scripts/gazebo.material</uri>
            </script>
          </material>
        </visual>
        <self_collide>0</self_collide>
        <enable_wind>0</enable_wind>
        <kinematic>0</kinematic>
      </link>
      <joint name='j1' type='revolute'>
        <pose relative_to='base_turn_rot'>0 0 0.0385 0 1.57 1.57</pose>
        <parent>base_turn_rot</parent>
        <child>dyn2_r</child>
        <axis>
          <xyz>0 0 1</xyz>
          <limit>
            <lower>-3.14</lower>
            <upper>3.14</upper>
            <effort>300</effort>
            <velocity>0.1</velocity>
          </limit>
          <dynamics>
            <spring_reference>0</spring_reference>
            <spring_stiffness>0</spring_stiffness>
          </dynamics>
        </axis>
      </joint>
      <link name='dyn2_r'>
        <pose relative_to='j1'>0 0 0 0 -0 0</pose>
        <inertial>
          <pose>-0.07925 2.6e-05 -0.001 0 -0 0</pose>
          <mass>0.2</mass>
          <inertia>
            <ixx>193.557</ixx>
            <ixy>0.11657</ixy>
            <ixz>-0.0280543</ixz>
            <iyy>228.851</iyy>
            <iyz>0.0162256</iyz>
            <izz>173.297</izz>
          </inertia>
        </inertial>
        <collision name='dyn2_r_fixed_joint_lump__f4_collision'>
          <pose>-0.032 -1.2e-05 -0.003 1.57159 1.57079 3.14159</pose>
          <geometry>
            <box>
              <size>0.06 0.1 0.035</size>
            </box>
          </geometry>
          <surface>
            <contact>
              <ode/>
            </contact>
            <friction>
              <ode/>
              <torsional>
                <ode/>
              </torsional>
            </friction>
            <bounce/>
          </surface>
          <max_contacts>10</max_contacts>
        </collision>
        <collision name='dyn2_r_fixed_joint_lump__dyn3_collision_1'>
          <pose>-0.1115 4.8e-05 0.001 0.001594 -0.000795 -0.00239</pose>
          <geometry>
            <box>
              <size>0.08 0.035 0.045</size>
            </box>
          </geometry>
          <surface>
            <contact>
              <ode/>
            </contact>
            <friction>
              <ode/>
              <torsional>
                <ode/>
              </torsional>
            </friction>
            <bounce/>
          </surface>
          <max_contacts>10</max_contacts>
        </collision>
        <visual name='dyn2_r_fixed_joint_lump__f4_visual'>
          <pose>-0.047 0 -0.003 1.57159 1.57079 3.14159</pose>
          <geometry>
            <mesh>
              <scale>0.001 0.001 0.001</scale>
              <uri>/home/luigi/catkin_ws/src/arm_description/meshes/f4_n_f3.stl</uri>
            </mesh>
          </geometry>
          <material>
            <script>
              <name>Gazebo/Red</name>
              <uri>file://media/materials/scripts/gazebo.material</uri>
            </script>
          </material>
        </visual>
        <visual name='dyn2_r_fixed_joint_lump__dyn3_visual_1'>
          <pose>-0.1115 4.8e-05 0.001 0.001594 -0.000795 -0.00239</pose>
          <geometry>
            <mesh>
              <scale>0.01 0.01 0.01</scale>
              <uri>/home/luigi/catkin_ws/src/arm_description/meshes/dyn.stl</uri>
            </mesh>
          </geometry>
          <material>
            <script>
              <name>Gazebo/Black</name>
              <uri>file://media/materials/scripts/gazebo.material</uri>
            </script>
          </material>
        </visual>
        <self_collide>0</self_collide>
        <enable_wind>0</enable_wind>
        <kinematic>0</kinematic>
      </link>
      <joint name='j2' type='revolute'>
        <pose relative_to='dyn2_r'>-0.1115 4.8e-05 0.001 0.001594 -0.000795 -0.00239</pose>
        <parent>dyn2_r</parent>
        <child>dyn3_r</child>
        <axis>
          <xyz>0 0 1</xyz>
          <limit>
            <lower>-3.14</lower>
            <upper>3.14</upper>
            <effort>300</effort>
            <velocity>0.1</velocity>
          </limit>
          <dynamics>
            <spring_reference>0</spring_reference>
            <spring_stiffness>0</spring_stiffness>
          </dynamics>
        </axis>
      </joint>
      <link name='dyn3_r'>
        <pose relative_to='j2'>0 0 0 0 -0 0</pose>
        <inertial>
          <pose>-0.0785 3e-06 0 0 -0 0</pose>
          <mass>0.2</mass>
          <inertia>
            <ixx>8.78059e+06</ixx>
            <ixy>788.817</ixy>
            <ixz>-0.0280899</ixz>
            <iyy>1.72942e+07</iyy>
            <iyz>0.0161395</iyz>
            <izz>1.13132e+07</izz>
          </inertia>
        </inertial>
        <collision name='dyn3_r_fixed_joint_lump__f5_collision'>
          <pose>-0.031 1.1e-05 -0.002012 1.57089 1.57079 -3.14159</pose>
          <geometry>
            <box>
              <size>0.06 0.1 0.035</size>
            </box>
          </geometry>
          <surface>
            <contact>
              <ode/>
            </contact>
            <friction>
              <ode/>
              <torsional>
                <ode/>
              </torsional>
            </friction>
            <bounce/>
          </surface>
          <max_contacts>10</max_contacts>
        </collision>
        <collision name='dyn3_r_fixed_joint_lump__dyn4_collision_1'>
          <pose>-0.110997 -4.6e-05 0.002052 0.000797 -0 0.000611</pose>
          <geometry>
            <box>
              <size>0.08 0.035 0.045</size>
            </box>
          </geometry>
          <surface>
            <contact>
              <ode/>
            </contact>
            <friction>
              <ode/>
              <torsional>
                <ode/>
              </torsional>
            </friction>
            <bounce/>
          </surface>
          <max_contacts>10</max_contacts>
        </collision>
        <visual name='dyn3_r_fixed_joint_lump__f5_visual'>
          <pose>-0.046 0 -0.002 1.57089 1.57079 -3.14159</pose>
          <geometry>
            <mesh>
              <scale>0.001 0.001 0.001</scale>
              <uri>/home/luigi/catkin_ws/src/arm_description/meshes/f4_n_f3.stl</uri>
            </mesh>
          </geometry>
          <material>
            <script>
              <name>Gazebo/Red</name>
              <uri>file://media/materials/scripts/gazebo.material</uri>
            </script>
          </material>
        </visual>
        <visual name='dyn3_r_fixed_joint_lump__dyn4_visual_1'>
          <pose>-0.110997 -4.6e-05 0.002052 0.000797 -0 0.000611</pose>
          <geometry>
            <mesh>
              <scale>0.01 0.01 0.01</scale>
              <uri>/home/luigi/catkin_ws/src/arm_description/meshes/dyn.stl</uri>
            </mesh>
          </geometry>
          <material>
            <script>
              <name>Gazebo/Black</name>
              <uri>file://media/materials/scripts/gazebo.material</uri>
            </script>
          </material>
        </visual>
        <self_collide>0</self_collide>
        <enable_wind>0</enable_wind>
        <kinematic>0</kinematic>
      </link>
      <joint name='j3' type='revolute'>
        <pose relative_to='dyn3_r'>-0.110997 -4.6e-05 0.002052 0.000797 -0 0.000611</pose>
        <parent>dyn3_r</parent>
        <child>dyn4_r</child>
        <axis>
          <xyz>0 0 1</xyz>
          <limit>
            <lower>-3.14</lower>
            <upper>3.14</upper>
            <effort>300</effort>
            <velocity>0.1</velocity>
          </limit>
          <dynamics>
            <spring_reference>0</spring_reference>
            <spring_stiffness>0</spring_stiffness>
          </dynamics>
        </axis>
      </joint>
      <link name='dyn4_r'>
        <pose relative_to='j3'>0 0 0 0 -0 0</pose>
        <inertial>
          <pose>-0.054406 -0.00563 -3.8e-05 0 -0 0</pose>
          <mass>0.5</mass>
          <inertia>
            <ixx>450.89</ixx>
            <ixy>-0.0926023</ixy>
            <ixz>-0.00010229</ixz>
            <iyy>567.221</iyy>
            <iyz>0.110648</iyz>
            <izz>471.15</izz>
          </inertia>
        </inertial>
        <collision name='dyn4_r_fixed_joint_lump__wrist_collision'>
          <pose>-0.002 -0.012976 0.003 -0.000793 1.57079 -3.14159</pose>
          <geometry>
            <box>
              <size>0.075 0.06 0.06</size>
            </box>
          </geometry>
          <surface>
            <contact>
              <ode/>
            </contact>
            <friction>
              <ode/>
              <torsional>
                <ode/>
              </torsional>
            </friction>
            <bounce/>
          </surface>
          <max_contacts>10</max_contacts>
        </collision>
        <collision name='dyn4_r_fixed_joint_lump__dyn5_collision_1'>
          <pose>-0.044521 -4.7e-05 -0.00081 1.5708 -0 -1.5692</pose>
          <geometry>
            <box>
              <size>0.08 0.035 0.045</size>
            </box>
          </geometry>
          <surface>
            <contact>
              <ode/>
            </contact>
            <friction>
              <ode/>
              <torsional>
                <ode/>
              </torsional>
            </friction>
            <bounce/>
          </surface>
          <max_contacts>10</max_contacts>
        </collision>
        <collision name='dyn4_r_fixed_joint_lump__crawer_base_collision_2'>
          <pose>-0.063505 -0.010077 -0.000806 -3.1392 -1.57079 3.14159</pose>
          <geometry>
            <box>
              <size>0.11 0.06 0.01</size>
            </box>
          </geometry>
          <surface>
            <contact>
              <ode/>
            </contact>
            <friction>
              <ode/>
              <torsional>
                <ode/>
              </torsional>
            </friction>
            <bounce/>
          </surface>
          <max_contacts>10</max_contacts>
        </collision>
        <collision name='dyn4_r_fixed_joint_lump__crawer_left_collision_3'>
          <pose>-0.073521 -6.9e-05 -0.030798 3.1408 -0.000797 -3.14</pose>
          <geometry>
            <box>
              <size>0.1 0.035 0.055</size>
            </box>
          </geometry>
          <surface>
            <contact>
              <ode/>
            </contact>
            <friction>
              <ode/>
              <torsional>
                <ode/>
              </torsional>
            </friction>
            <bounce/>
          </surface>
          <max_contacts>10</max_contacts>
        </collision>
        <collision name='dyn4_r_fixed_joint_lump__crawer_right_collision_4'>
          <pose>-0.073521 -0.000117 0.029202 -0.000889 -0.000797 -3.14</pose>
          <geometry>
            <box>
              <size>0.1 0.035 0.055</size>
            </box>
          </geometry>
          <surface>
            <contact>
              <ode/>
            </contact>
            <friction>
              <ode/>
              <torsional>
                <ode/>
              </torsional>
            </friction>
            <bounce/>
          </surface>
          <max_contacts>10</max_contacts>
        </collision>
        <visual name='dyn4_r_fixed_joint_lump__wrist_visual'>
          <pose>-0.017 -0.013 0.003 -0.000793 1.57079 -3.14159</pose>
          <geometry>
            <mesh>
              <scale>0.001 0.001 0.001</scale>
              <uri>/home/luigi/catkin_ws/src/arm_description/meshes/wrist.stl</uri>
            </mesh>
          </geometry>
          <material>
            <script>
              <name>Gazebo/Red</name>
              <uri>file://media/materials/scripts/gazebo.material</uri>
            </script>
          </material>
        </visual>
        <visual name='dyn4_r_fixed_joint_lump__dyn5_visual_1'>
          <pose>-0.044521 -4.7e-05 -0.00081 1.5708 -0 -1.5692</pose>
          <geometry>
            <mesh>
              <scale>0.01 0.01 0.01</scale>
              <uri>/home/luigi/catkin_ws/src/arm_description/meshes/dyn.stl</uri>
            </mesh>
          </geometry>
          <material>
            <script>
              <name>Gazebo/Black</name>
              <uri>file://media/materials/scripts/gazebo.material</uri>
            </script>
          </material>
        </visual>
        <visual name='dyn4_r_fixed_joint_lump__crawer_base_visual_2'>
          <pose>-0.063497 -0.015077 -0.00081 -3.1392 -1.57079 3.14159</pose>
          <geometry>
            <mesh>
              <scale>0.001 0.001 0.001</scale>
              <uri>/home/luigi/catkin_ws/src/arm_description/meshes/the_crawer_base.stl</uri>
            </mesh>
          </geometry>
          <material>
            <script>
              <name>Gazebo/Red</name>
              <uri>file://media/materials/scripts/gazebo.material</uri>
            </script>
          </material>
        </visual>
        <visual name='dyn4_r_fixed_joint_lump__crawer_left_visual_3'>
          <pose>-0.073521 -6.9e-05 -0.030798 3.1408 -0.000797 -3.14</pose>
          <geometry>
            <mesh>
              <scale>0.001 0.001 0.001</scale>
              <uri>/home/luigi/catkin_ws/src/arm_description/meshes/the_crawer.stl</uri>
            </mesh>
          </geometry>
          <material>
            <script>
              <name>Gazebo/Red</name>
              <uri>file://media/materials/scripts/gazebo.material</uri>
            </script>
          </material>
        </visual>
        <visual name='dyn4_r_fixed_joint_lump__crawer_right_visual_4'>
          <pose>-0.073521 -0.000117 0.029202 -0.000889 -0.000797 -3.14</pose>
          <geometry>
            <mesh>
              <scale>0.001 0.001 0.001</scale>
              <uri>/home/luigi/catkin_ws/src/arm_description/meshes/the_crawer.stl</uri>
            </mesh>
          </geometry>
          <material>
            <script>
              <name>Gazebo/Red</name>
              <uri>file://media/materials/scripts/gazebo.material</uri>
            </script>
          </material>
        </visual>
        <self_collide>0</self_collide>
        <enable_wind>0</enable_wind>
        <kinematic>0</kinematic>
      </link>
      <static>0</static>
      <plugin name='gazebo_ros_control' filename='libgazebo_ros_control.so'>
        <robotNamespace>/arm</robotNamespace>
      </plugin>
      <pose>0 0 0 0 -0 0</pose>
    </model>
    <model name='ambulance'>
      <static>1</static>
      <link name='link'>
        <collision name='collision'>
          <geometry>
            <mesh>
              <scale>0.0254 0.0254 0.0254</scale>
              <uri>model://ambulance/meshes/ambulance.obj</uri>
            </mesh>
          </geometry>
          <max_contacts>10</max_contacts>
          <surface>
            <contact>
              <ode/>
            </contact>
            <bounce/>
            <friction>
              <torsional>
                <ode/>
              </torsional>
              <ode/>
            </friction>
          </surface>
        </collision>
        <visual name='visual'>
          <geometry>
            <mesh>
              <scale>0.0254 0.0254 0.0254</scale>
              <uri>model://ambulance/meshes/ambulance.obj</uri>
            </mesh>
          </geometry>
        </visual>
        <self_collide>0</self_collide>
        <enable_wind>0</enable_wind>
        <kinematic>0</kinematic>
      </link>
      <pose>-0.079927 5.02562 0 0 -0 0</pose>
    </model>
    <state world_name='default'>
      <sim_time>258 239000000</sim_time>
      <real_time>259 534166909</real_time>
      <wall_time>1698682999 631756797</wall_time>
      <iterations>258239</iterations>
      <model name='ambulance'>
        <pose>6.89334 0.253808 0 0 -0 0</pose>
        <scale>1 1 1</scale>
        <link name='link'>
          <pose>6.89334 0.253808 0 0 -0 0</pose>
          <velocity>0 0 0 0 -0 0</velocity>
          <acceleration>0 0 0 0 -0 0</acceleration>
          <wrench>0 0 0 0 -0 0</wrench>
        </link>
      </model>
      <model name='arm'>
        <pose>-0 0 0.049995 -0 -0 -0</pose>
        <scale>1 1 1</scale>
        <link name='base_link'>
          <pose>-0 0 0.049995 -0 -0 -0</pose>
          <velocity>-0 0 -0.004925 0 -0 0</velocity>
          <acceleration>-0 0 -9.84991 0 -0 0</acceleration>
          <wrench>-0 0 -1.97097 0 -0 0</wrench>
        </link>
        <link name='base_turn_rot'>
          <pose>-0.0011 0.0045 0.112995 0 -0 -1.57</pose>
          <velocity>-0 -0 -0.004916 0 -0 0</velocity>
          <acceleration>-0 0 -9.83133 0 -0 0</acceleration>
          <wrench>-0 0 -1.96627 0 -0 0</wrench>
        </link>
        <link name='dyn2_r'>
          <pose>-0.0011 0.0045 0.151495 0 1.57 0</pose>
          <velocity>-0 -0 -0.004906 0 -0 0</velocity>
          <acceleration>0 -0 -9.81103 0 -0 0</acceleration>
          <wrench>0 -0 -1.96221 0 -0 0</wrench>
        </link>
        <link name='dyn3_r'>
          <pose>-0.000189 0.004548 0.262996 -0.981781 1.56793 -0.983375</pose>
          <velocity>-0 0 -0.004895 0 -0 0</velocity>
          <acceleration>0 -0 -9.79025 -0 -0 -0</acceleration>
          <wrench>0 -0 -1.95805 0 -0 0</wrench>
        </link>
        <link name='dyn4_r'>
          <pose>0.001686 0.004764 0.373996 -0.838331 1.56841 -0.840721</pose>
          <velocity>-0 -0 -0.004883 0 -0 0</velocity>
          <acceleration>0 -0 -9.76698 0 -0 0</acceleration>
          <wrench>0 -0 -4.88349 0 -0 0</wrench>
        </link>
      </model>
      <model name='ground_plane'>
        <pose>0 0 0 0 -0 0</pose>
        <scale>1 1 1</scale>
        <link name='link'>
          <pose>0 0 0 0 -0 0</pose>
          <velocity>0 0 0 0 -0 0</velocity>
          <acceleration>0 0 0 0 -0 0</acceleration>
          <wrench>0 0 0 0 -0 0</wrench>
        </link>
      </model>
      <light name='sun'>
        <pose>0 0 10 0 -0 0</pose>
      </light>
    </state>
    <gui fullscreen='0'>
      <camera name='user_camera'>
        <pose>-3.97358 -9.70339 7.81228 0 0.579643 0.892186</pose>
        <view_controller>orbit</view_controller>
        <projection_type>perspective</projection_type>
      </camera>
    </gui>
  </world>
</sdf>
